Workbook

Sheet Kits
A1: HV Swim Bendigo — merchandise kits
A2: Every line below is a product that exists in the HV Swim catalogue. Retail prices are the current preview prices from the build.
A3: Blue cells are for you to fill in: supplier, quoted unit cost, and the kit price you decide to sell at.
A5: Kit | B5: Who it is for | C5: SKU | D5: Product | E5: Category | F5: Suggested route | G5: Retail (ea) | H5: Qty | I5: Line retail | J5: Supplier | K5: Quoted cost (ea) | L5: Line cost
A6: First Splash Kit | B6: New swimmers | C6: HV-GOGGLES | D6: HV Swim Goggles | E6: Equipment | F6: Specialist swim supplier | G6: 24.95 | H6: 1 | I6: =G6*H6 -> 24.95 | L6: =K6*H6 -> 0
A7: First Splash Kit | B7: New swimmers | C7: HV-CAP | D7: HV Swim Team Cap | E7: Caps | F7: VistaPrint or Printify | G7: 14.95 | H7: 1 | I7: =G7*H7 -> 14.95 | L7: =K7*H7 -> 0
A8: First Splash Kit | B8: New swimmers | C8: HV-MINI-HOODED-TOWEL | D8: HV Swim Mini Hooded Towel | E8: Towels | F8: VistaPrint or textile supplier | G8: 49.95 | H8: 1 | I8: =G8*H8 -> 49.95 | L8: =K8*H8 -> 0
A9: First Splash Kit | B9: New swimmers | C9: HV-BOTTLE | D9: HV Swim Named Insulated Bottle | E9: Bottles | F9: VistaPrint / bulk drinkware | G9: 29.95 | H9: 1 | I9: =G9*H9 -> 29.95 | L9: =K9*H9 -> 0
D10: First Splash Kit — kit total | I10: =SUM(I6:I9) -> 119.8 | L10: =SUM(L6:L9) -> 0
A12: Lesson Day Kit | B12: Weekly swimmers | C12: HV-RASHIE | D12: HV Swim Kids Rashie | E12: Swimwear | F12: Specialist swim supplier | G12: 44.95 | H12: 1 | I12: =G12*H12 -> 44.95 | L12: =K12*H12 -> 0
A13: Lesson Day Kit | B13: Weekly swimmers | C13: HV-SWIM-SHORTS | D13: HV Swim Kids Swim Shorts | E13: Swimwear | F13: Specialist swim supplier | G13: 39.95 | H13: 1 | I13: =G13*H13 -> 39.95 | L13: =K13*H13 -> 0
A14: Lesson Day Kit | B14: Weekly swimmers | C14: HV-GOGGLES | D14: HV Swim Goggles | E14: Equipment | F14: Specialist swim supplier | G14: 24.95 | H14: 1 | I14: =G14*H14 -> 24.95 | L14: =K14*H14 -> 0
A15: Lesson Day Kit | B15: Weekly swimmers | C15: HV-CAP | D15: HV Swim Team Cap | E15: Caps | F15: VistaPrint or Printify | G15: 14.95 | H15: 1 | I15: =G15*H15 -> 14.95 | L15: =K15*H15 -> 0
A16: Lesson Day Kit | B16: Weekly swimmers | C16: HV-TRAINING-MITTS | D16: HV Swim Silicone Training Mitts | E16: Equipment | F16: Specialist swim supplier | G16: 19.95 | H16: 1 | I16: =G16*H16 -> 19.95 | L16: =K16*H16 -> 0
A17: Lesson Day Kit | B17: Weekly swimmers | C17: HV-HOODED-TOWEL | D17: HV Swim Embroidered Hooded Towel Poncho | E17: Towels | F17: VistaPrint or textile supplier | G17: 59.95 | H17: 1 | I17: =G17*H17 -> 59.95 | L17: =K17*H17 -> 0
A18: Lesson Day Kit | B18: Weekly swimmers | C18: HV-BAG | D18: HV Swim Pool-Deck Bag | E18: Bags | F18: Printify or specialist | G18: 39.95 | H18: 1 | I18: =G18*H18 -> 39.95 | L18: =K18*H18 -> 0
A19: Lesson Day Kit | B19: Weekly swimmers | C19: HV-BOTTLE | D19: HV Swim Named Insulated Bottle | E19: Bottles | F19: VistaPrint / bulk drinkware | G19: 29.95 | H19: 1 | I19: =G19*H19 -> 29.95 | L19: =K19*H19 -> 0
D20: Lesson Day Kit — kit total | I20: =SUM(I12:I19) -> 274.6 | L20: =SUM(L12:L19) -> 0
A22: Sun & Season Kit | B22: Outdoor season | C22: HV-KIDS-SUN-HAT | D22: HV Swim Kids Sun Hat | E22: Caps | F22: VistaPrint or Printify | G22: 29.95 | H22: 1 | I22: =G22*H22 -> 29.95 | L22: =K22*H22 -> 0
A23: Sun & Season Kit | B23: Outdoor season | C23: HV-RASHIE | D23: HV Swim Kids Rashie | E23: Swimwear | F23: Specialist swim supplier | G23: 44.95 | H23: 1 | I23: =G23*H23 -> 44.95 | L23: =K23*H23 -> 0
A24: Sun & Season Kit | B24: Outdoor season | C24: HV-TOWEL | D24: HV Swim Premium Embroidered Towel | E24: Towels | F24: VistaPrint or textile supplier | G24: 39.95 | H24: 1 | I24: =G24*H24 -> 39.95 | L24: =K24*H24 -> 0
A25: Sun & Season Kit | B25: Outdoor season | C25: HV-BOTTLE | D25: HV Swim Named Insulated Bottle | E25: Bottles | F25: VistaPrint / bulk drinkware | G25: 29.95 | H25: 1 | I25: =G25*H25 -> 29.95 | L25: =K25*H25 -> 0
A26: Sun & Season Kit | B26: Outdoor season | C26: HV-GOGGLES | D26: HV Swim Goggles | E26: Equipment | F26: Specialist swim supplier | G26: 24.95 | H26: 1 | I26: =G26*H26 -> 24.95 | L26: =K26*H26 -> 0
D27: Sun & Season Kit — kit total | I27: =SUM(I22:I26) -> 169.75 | L27: =SUM(L22:L26) -> 0
A29: Poolside Parent Kit | B29: Parents on the deck | C29: HV-FAMILY-CREW | D29: HV Swim Family Club Crew | E29: Lifestyle | F29: Printify → Shopify | G29: 64.95 | H29: 1 | I29: =G29*H29 -> 64.95 | L29: =K29*H29 -> 0
A30: Poolside Parent Kit | B30: Parents on the deck | C30: HV-INSULATED-TUMBLER | D30: HV Swim Insulated Coffee Cup | E30: Drinkware | F30: VistaPrint / bulk drinkware | G30: 34.95 | H30: 1 | I30: =G30*H30 -> 34.95 | L30: =K30*H30 -> 0
A31: Poolside Parent Kit | B31: Parents on the deck | C31: HV-TOWEL | D31: HV Swim Premium Embroidered Towel | E31: Towels | F31: VistaPrint or textile supplier | G31: 39.95 | H31: 1 | I31: =G31*H31 -> 39.95 | L31: =K31*H31 -> 0
D32: Poolside Parent Kit — kit total | I32: =SUM(I29:I31) -> 139.85 | L32: =SUM(L29:L31) -> 0
A34: Family Club Kit | B34: Families + supporters | C34: HV-FAMILY-TEE | D34: HV Swim Family Club Tee | E34: Lifestyle | F34: Printify → Shopify | G34: 34.95 | H34: 1 | I34: =G34*H34 -> 34.95 | L34: =K34*H34 -> 0
A35: Family Club Kit | B35: Families + supporters | C35: HV-FAMILY-CREW | D35: HV Swim Family Club Crew | E35: Lifestyle | F35: Printify → Shopify | G35: 64.95 | H35: 1 | I35: =G35*H35 -> 64.95 | L35: =K35*H35 -> 0
A36: Family Club Kit | B36: Families + supporters | C36: HV-BOTTLE | D36: HV Swim Named Insulated Bottle | E36: Bottles | F36: VistaPrint / bulk drinkware | G36: 29.95 | H36: 1 | I36: =G36*H36 -> 29.95 | L36: =K36*H36 -> 0
A37: Family Club Kit | B37: Families + supporters | C37: HV-TOWEL | D37: HV Swim Premium Embroidered Towel | E37: Towels | F37: VistaPrint or textile supplier | G37: 39.95 | H37: 1 | I37: =G37*H37 -> 39.95 | L37: =K37*H37 -> 0
D38: Family Club Kit — kit total | I38: =SUM(I34:I37) -> 169.8 | L38: =SUM(L34:L37) -> 0
A40: Instructor Uniform | B40: Every instructor | C40: HV-STAFF-POLO | D40: HV Swim Staff Polo | E40: Uniforms | F40: Uniform supplier (embroidery) | G40: 44.95 | H40: 1 | I40: =G40*H40 -> 44.95 | L40: =K40*H40 -> 0
A41: Instructor Uniform | B41: Every instructor | C41: HV-STAFF-TEE | D41: HV Swim Staff Performance Shirt | E41: Uniforms | F41: Uniform supplier (embroidery) | G41: 39.95 | H41: 1 | I41: =G41*H41 -> 39.95 | L41: =K41*H41 -> 0
A42: Instructor Uniform | B42: Every instructor | C42: HV-STAFF-SHORTS | D42: HV Swim Staff Deck Shorts | E42: Uniforms | F42: Uniform supplier (embroidery) | G42: 44.95 | H42: 1 | I42: =G42*H42 -> 44.95 | L42: =K42*H42 -> 0
A43: Instructor Uniform | B43: Every instructor | C43: HV-INSTRUCTOR-CAP | D43: HV Swim Instructor Cap | E43: Uniforms | F43: Uniform supplier (embroidery) | G43: 24.95 | H43: 1 | I43: =G43*H43 -> 24.95 | L43: =K43*H43 -> 0
A44: Instructor Uniform | B44: Every instructor | C44: HV-BOTTLE | D44: HV Swim Named Insulated Bottle | E44: Bottles | F44: VistaPrint / bulk drinkware | G44: 29.95 | H44: 1 | I44: =G44*H44 -> 29.95 | L44: =K44*H44 -> 0
D45: Instructor Uniform — kit total | I45: =SUM(I40:I44) -> 184.75 | L45: =SUM(L40:L44) -> 0
A47: Winter Deck Uniform | B47: Cold-weather shifts | C47: HV-STAFF-PUFFER-VEST | D47: HV Swim Staff Puffer Vest | E47: Uniforms | F47: Uniform supplier (embroidery) | G47: 89.95 | H47: 1 | I47: =G47*H47 -> 89.95 | L47: =K47*H47 -> 0
...

Sheet Kit summary
A1: Kit summary
A2: Kit price is yours to set. Margin updates automatically once you enter it.
A4: Group | B4: Kit | C4: Who it is for | D4: Items | E4: Components retail | F4: Kit price (you set) | G4: Difference | H4: Margin on retail
A5: For the swimmer | B5: First Splash Kit | C5: New swimmers | D5: 4 | E5: =Kits!I10 -> 119.8 | G5: =IF(F5="","",F5-E5) | H5: =IFERROR(IF(F5="","",(F5-E5)/F5),"")
A6: For the swimmer | B6: Lesson Day Kit | C6: Weekly swimmers | D6: 8 | E6: =Kits!I20 -> 274.6 | G6: =IF(F6="","",F6-E6) | H6: =IFERROR(IF(F6="","",(F6-E6)/F6),"")
A7: For the swimmer | B7: Sun & Season Kit | C7: Outdoor season | D7: 5 | E7: =Kits!I27 -> 169.75 | G7: =IF(F7="","",F7-E7) | H7: =IFERROR(IF(F7="","",(F7-E7)/F7),"")
A8: Parents and families | B8: Poolside Parent Kit | C8: Parents on the deck | D8: 3 | E8: =Kits!I32 -> 139.85 | G8: =IF(F8="","",F8-E8) | H8: =IFERROR(IF(F8="","",(F8-E8)/F8),"")
A9: Parents and families | B9: Family Club Kit | C9: Families + supporters | D9: 4 | E9: =Kits!I38 -> 169.8 | G9: =IF(F9="","",F9-E9) | H9: =IFERROR(IF(F9="","",(F9-E9)/F9),"")
A10: Staff uniform | B10: Instructor Uniform | C10: Every instructor | D10: 5 | E10: =Kits!I45 -> 184.75 | G10: =IF(F10="","",F10-E10) | H10: =IFERROR(IF(F10="","",(F10-E10)/F10),"")
A11: Staff uniform | B11: Winter Deck Uniform | C11: Cold-weather shifts | D11: 5 | E11: =Kits!I52 -> 379.75 | G11: =IF(F11="","",F11-E11) | H11: =IFERROR(IF(F11="","",(F11-E11)/F11),"")
A13: Components retail is the sum of the individual product prices, not a bundle price.
A14: Source: HV Swim product catalogue, backend/database.py seed, as at 30 Aug 2026.
